Workbook

Sheet Dashboard
A1: Benefit growth test - 100 projects, 60-yr horizon (2026-2085): raw, growth, and growth with no cash penalty
A2: Raw = LIN40 benefits as-is. Growth = calendar-year real growth U(1%,3%) (project 1 +3%, project 28 -2%). Envelope 210 $M p.a. = max(pro-rata s2000 124.6, largest single-project annual spend 206.9) rounded up to $10M, so every project fits without pre-banking. All values link to the model sheets.
A4: Headline | B4: Raw | C4: Growth | D4: Growth, no cash penalty | F4: Schedule shift by growth band (growth vs raw)
A5: Total PV benefits ($M) | B5: ='Raw profile'!J17 -> 7410.1203 | C5: ='Growth profile'!J17 -> 13627.303 | D5: ='Growth (no penalty)'!J17 -> 13893.822 | F5: Growth band | G5: Projects | H5: Avg shift (yrs) | I5: Deferred | J5: Pinned to 2085 | K5: Accelerated
A6: Project 1 start year (BCR 7, +3%) | B6: ='Raw profile'!I24 -> 2026 | C6: ='Growth profile'!I24 -> 2039 | D6: ='Growth (no penalty)'!I24 -> 2040 | F6: shrinking | G6: =COUNTIF(Comparison!$N$5:$N$104,F6) -> 1 | H6: =IFERROR(AVERAGEIF(Comparison!$N$5:$N$104,F6,Comparison!$I$5:$I$104),0) -> 0 | I6: =COUNTIFS(Comparison!$N$5:$N$104,F6,Comparison!$I$5:$I$104,">0") -> 0 | J6: =COUNTIFS(Comparison!$N$5:$N$104,F6,Comparison!$L$5:$L$104,2085,Comparison!$I$5:$I$104,">0") -> 0 | K6: =COUNTIFS(Comparison!$N$5:$N$104,F6,Comparison!$I$5:$I$104,"<0") -> 0
A7: project 28 start year (-2%) | B7: =INDEX('Raw profile'!I24:I123,MATCH("project 28",'Raw profile'!A24:A123,0)) -> 2026 | C7: =INDEX('Growth profile'!I24:I123,MATCH("project 28",'Growth profile'!A24:A123,0)) -> 2026 | D7: =INDEX('Growth (no penalty)'!I24:I123,MATCH("project 28",'Growth (no penalty)'!A24:A123,0)) -> 2026 | F7: under 1.5% | G7: =COUNTIF(Comparison!$N$5:$N$104,F7) -> 28 | H7: =IFERROR(AVERAGEIF(Comparison!$N$5:$N$104,F7,Comparison!$I$5:$I$104),0) -> -7.8214286 | I7: =COUNTIFS(Comparison!$N$5:$N$104,F7,Comparison!$I$5:$I$104,">0") -> 1 | J7: =COUNTIFS(Comparison!$N$5:$N$104,F7,Comparison!$L$5:$L$104,2085,Comparison!$I$5:$I$104,">0") -> 0 | K7: =COUNTIFS(Comparison!$N$5:$N$104,F7,Comparison!$I$5:$I$104,"<0") -> 21
A8: Last construction year | B8: ='Raw profile'!B14 -> 2044 | C8: ='Growth profile'!B14 -> 2044 | D8: ='Growth (no penalty)'!B14 -> 2045 | F8: 1.5% to 1.8% | G8: =COUNTIF(Comparison!$N$5:$N$104,F8) -> 13 | H8: =IFERROR(AVERAGEIF(Comparison!$N$5:$N$104,F8,Comparison!$I$5:$I$104),0) -> -6.5384615 | I8: =COUNTIFS(Comparison!$N$5:$N$104,F8,Comparison!$I$5:$I$104,">0") -> 0 | J8: =COUNTIFS(Comparison!$N$5:$N$104,F8,Comparison!$L$5:$L$104,2085,Comparison!$I$5:$I$104,">0") -> 0 | K8: =COUNTIFS(Comparison!$N$5:$N$104,F8,Comparison!$I$5:$I$104,"<0") -> 9
A9: Max annual spend / envelope | B9: ='Raw profile'!J8 -> 1.2079536 | C9: ='Growth profile'!J8 -> 1.1859557 | D9: ='Growth (no penalty)'!J8 -> 4.0557503 | F9: 1.8% and over | G9: =COUNTIF(Comparison!$N$5:$N$104,F9) -> 58 | H9: =IFERROR(AVERAGEIF(Comparison!$N$5:$N$104,F9,Comparison!$I$5:$I$104),0) -> 2.8103448 | I9: =COUNTIFS(Comparison!$N$5:$N$104,F9,Comparison!$I$5:$I$104,">0") -> 31 | J9: =COUNTIFS(Comparison!$N$5:$N$104,F9,Comparison!$L$5:$L$104,2085,Comparison!$I$5:$I$104,">0") -> 0 | K9: =COUNTIFS(Comparison!$N$5:$N$104,F9,Comparison!$I$5:$I$104,"<0") -> 25
A10: Years with spend above envelope | B10: ='Raw profile'!J9 -> 12 | C10: ='Growth profile'!J9 -> 8 | D10: ='Growth (no penalty)'!J9 -> 6 | F10: All | G10: =SUM(G6:G9) -> 100 | H10: =IFERROR(AVERAGE(Comparison!$I$5:$I$104),0) -> -1.41 | I10: =SUM(I6:I9) -> 32 | J10: =SUM(J6:J9) -> 0 | K10: =SUM(K6:K9) -> 55
A11: Peak balance carried while building ($M) | B11: ='Raw profile'!J5 -> 47.2655 | C11: ='Growth profile'!J5 -> 44.683444 | D11: ='Growth (no penalty)'!J5 -> 1691.0532
A12: Average balance carried while building ($M) | B12: ='Raw profile'!J6 -> 5.2065596 | C12: ='Growth profile'!J6 -> 24.428736 | D12: ='Growth (no penalty)'!J6 -> 630.20539 | F12: Full per-project table: 'Comparison'. Gantt: 'Gantt'. Odd cases: 'Fringe cases'.
A13: Years holding cash above penalty-free cap | B13: ='Raw profile'!J7 -> 1 | C13: ='Growth profile'!J7 -> 5 | D13: ='Growth (no penalty)'!J7 -> 13
A14: Funded years with zero spend | B14: ='Raw profile'!J10 -> 0 | C14: ='Growth profile'!J10 -> 0 | D14: ='Growth (no penalty)'!J10 -> 0
A15: Benefit-years truncated at 2085 | B15: =SUM('Raw profile'!N24:N123) -> 0 | C15: =SUM('Growth profile'!N24:N123) -> 0 | D15: =SUM('Growth (no penalty)'!N24:N123) -> 0
A16: MindOpt status / gap | B16: OPTIMAL / 0.000% | C16: OPTIMAL / 0.000% | D16: OPTIMAL / 0.000%
A18: Annual spend vs funding envelope, closing balance and the penalty-free cash cap (2026-2050)
A79: BCR - Spend-weighted project average: raw vs growth vs growth with no cash penalty | E79: Each year: sum(project spend x project BCR) / total spend, BCR = PV benefits / PV cost as scheduled (MBCM 2% / 1.5%), as in the optimiser dashboard.
A101: BCR of projects starting each year (cost-weighted): raw vs growth vs no cash penalty | E101: Each start year: sum(project cost x project BCR) / sum(project cost) over projects starting that year. Blank = no starts. Shows the ranking directly, without spend-smearing.
A123: Portfolio PV BCR (cumulative), 2026-2085: raw vs growth vs no cash penalty | E123: Each year: PV of all benefits realised to date / PV of all spend to date (MBCM rates), as in the optimiser dashboard. Starts near zero while building; the 2085 value is the portfolio BCR.
A145: BCR of projects starting in each 3-year NLTP period (cost-weighted): raw vs growth vs no cash penalty | M145: First period starts (edit to align with NLTP boundaries): | U145: 2026
M146: NLTP period | N146: From | O146: To | P146: Raw BCR | Q146: Growth BCR | R146: No-penalty BCR | S146: Raw starts | T146: Growth starts | U146: No-penalty starts
M147: =N147&"-"&RIGHT(O147,2) -> 2026-28 | N147: =$U$145+0 -> 2026 | O147: =N147+2 -> 2028 | P147: =IFERROR(SUMPRODUCT(('Raw profile'!$I$24:$I$123>=$N147)*('Raw profile'!$I$24:$I$123<=$O147)*'Raw profile'!$E$24:$E$123*'Raw profile'!$S$24:$S$123)/SUMPRODUCT(('Raw profile'!$I$24:$I$123>=$N147)*('Raw profile'!$I$24:$I$123<=$O147)*'Raw profile'!$E$24:$E$123),NA()) -> 2.8559604 | Q147: =IFERROR(SUMPRODUCT(('Growth profile'!$I$24:$I$123>=$N147)*('Growth profile'!$I$24:$I$123<=$O147)*'Growth profile'!$E$24:$E$123*'Growth profile'!$S$24:$S$123)/SUMPRODUCT(('Growth profile'!$I$24:$I$123>=$N147)*('Growth profile'!$I$24:$I$123<=$O147)*'Growth profile'!$E$24:$E$123),NA()) -> 3.495899 | R147: =IFERROR(SUMPRODUCT(('Growth (no penalty)'!$I$24:$I$123>=$N147)*('Growth (no penalty)'!$I$24:$I$123<=$O147)*'Growth (no penalty)'!$E$24:$E$123*'Growth (no penalty)'!$S$24:$S$123)/SUMPRODUCT(('Growth (no penalty)'!$I$24:$I$123>=$N147)*('Growth (no penalty)'!$I$24:$I$123<=$O147)*'Growth (no penalty)'!$E$24:$E$123),NA()) -> 3.2877013 | S147: =SUMPRODUCT(('Raw profile'!$I$24:$I$123>=$N147)*('Raw profile'!$I$24:$I$123<=$O147)) -> 31 | T147: =SUMPRODUCT(('Growth profile'!$I$24:$I$123>=$N147)*('Growth profile'!$I$24:$I$123<=$O147)) -> 32 | U147: =SUMPRODUCT(('Growth (no penalty)'!$I$24:$I$123>=$N147)*('Growth (no penalty)'!$I$24:$I$123<=$O147)) -> 35
M148: =N148&"-"&RIGHT(O148,2) -> 2029-31 | N148: =$U$145+3 -> 2029 | O148: =N148+2 -> 2031 | P148: =IFERROR(SUMPRODUCT(('Raw profile'!$I$24:$I$123>=$N148)*('Raw profile'!$I$24:$I$123<=$O148)*'Raw profile'!$E$24:$E$123*'Raw profile'!$S$24:$S$123)/SUMPRODUCT(('Raw profile'!$I$24:$I$123>=$N148)*('Raw profile'!$I$24:$I$123<=$O148)*'Raw profile'!$E$24:$E$123),NA()) -> 2.2316235 | Q148: =IFERROR(SUMPRODUCT(('Growth profile'!$I$24:$I$123>=$N148)*('Growth profile'!$I$24:$I$123<=$O148)*'Growth profile'!$E$24:$E$123*'Growth profile'!$S$24:$S$123)/SUMPRODUCT(('Growth profile'!$I$24:$I$123>=$N148)*('Growth profile'!$I$24:$I$123<=$O148)*'Growth profile'!$E$24:$E$123),NA()) -> 3.5248422 | R148: =IFERROR(SUMPRODUCT(('Growth (no penalty)'!$I$24:$I$123>=$N148)*('Growth (no penalty)'!$I$24:$I$123<=$O148)*'Growth (no penalty)'!$E$24:$E$123*'Growth (no penalty)'!$S$24:$S$123)/SUMPRODUCT(('Growth (no penalty)'!$I$24:$I$123>=$N148)*('Growth (no penalty)'!$I$24:$I$123<=$O148)*'Growth (no penalty)'!$E$24:$E$123),NA()) -> 4.6945876 | S148: =SUMPRODUCT(('Raw profile'!$I$24:$I$123>=$N148)*('Raw profile'!$I$24:$I$123<=$O148)) -> 11 | T148: =SUMPRODUCT(('Growth profile'!$I$24:$I$123>=$N148)*('Growth profile'!$I$24:$I$123<=$O148)) -> 10 | U148: =SUMPRODUCT(('Growth (no penalty)'!$I$24:$I$123>=$N148)*('Growth (no penalty)'!$I$24:$I$123<=$O148)) -> 5
M149: =N149&"-"&RIGHT(O149,2) -> 2032-34 | N149: =$U$145+6 -> 2032 | O149: =N149+2 -> 2034 | P149: =IFERROR(SUMPRODUCT(('Raw profile'!$I$24:$I$123>=$N149)*('Raw profile'!$I$24:$I$123<=$O149)*'Raw profile'!$E$24:$E$123*'Raw profile'!$S$24:$S$123)/SUMPRODUCT(('Raw profile'!$I$24:$I$123>=$N149)*('Raw profile'!$I$24:$I$123<=$O149)*'Raw profile'!$E$24:$E$123),NA()) -> 1.9658065 | Q149: =IFERROR(SUMPRODUCT(('Growth profile'!$I$24:$I$123>=$N149)*('Growth profile'!$I$24:$I$123<=$O149)*'Growth profile'!$E$24:$E$123*'Growth profile'!$S$24:$S$123)/SUMPRODUCT(('Growth profile'!$I$24:$I$123>=$N149)*('Growth profile'!$I$24:$I$123<=$O149)*'Growth profile'!$E$24:$E$123),NA()) -> 3.9081502 | R149: =IFERROR(SUMPRODUCT(('Growth (no penalty)'!$I$24:$I$123>=$N149)*('Growth (no penalty)'!$I$24:$I$123<=$O149)*'Growth (no penalty)'!$E$24:$E$123*'Growth (no penalty)'!$S$24:$S$123)/SUMPRODUCT(('Growth (no penalty)'!$I$24:$I$123>=$N149)*('Growth (no penalty)'!$I$24:$I$123<=$O149)*'Growth (no penalty)'!$E$24:$E$123),NA()) -> 1.332184 | S149: =SUMPRODUCT(('Raw profile'!$I$24:$I$123>=$N149)*('Raw profile'!$I$24:$I$123<=$O149)) -> 6 | T149: =SUMPRODUCT(('Growth profile'!$I$24:$I$123>=$N149)*('Growth profile'!$I$24:$I$123<=$O149)) -> 23 | U149: =SUMPRODUCT(('Growth (no penalty)'!$I$24:$I$123>=$N149)*('Growth (no penalty)'!$I$24:$I$123<=$O149)) -> 1
M150: =N150&"-"&RIGHT(O150,2) -> 2035-37 | N150: =$U$145+9 -> 2035 | O150: =N150+2 -> 2037 | P150: =IFERROR(SUMPRODUCT(('Raw profile'!$I$24:$I$123>=$N150)*('Raw profile'!$I$24:$I$123<=$O150)*'Raw profile'!$E$24:$E$123*'Raw profile'!$S$24:$S$123)/SUMPRODUCT(('Raw profile'!$I$24:$I$123>=$N150)*('Raw profile'!$I$24:$I$123<=$O150)*'Raw profile'!$E$24:$E$123),NA()) -> 1.7312536 | Q150: =IFERROR(SUMPRODUCT(('Growth profile'!$I$24:$I$123>=$N150)*('Growth profile'!$I$24:$I$123<=$O150)*'Growth profile'!$E$24:$E$123*'Growth profile'!$S$24:$S$123)/SUMPRODUCT(('Growth profile'!$I$24:$I$123>=$N150)*('Growth profile'!$I$24:$I$123<=$O150)*'Growth profile'!$E$24:$E$123),NA()) -> 4.4315604 | R150: =IFERROR(SUMPRODUCT(('Growth (no penalty)'!$I$24:$I$123>=$N150)*('Growth (no penalty)'!$I$24:$I$123<=$O150)*'Growth (no penalty)'!$E$24:$E$123*'Growth (no penalty)'!$S$24:$S$123)/SUMPRODUCT(('Growth (no penalty)'!$I$24:$I$123>=$N150)*('Growth (no penalty)'!$I$24:$I$123<=$O150)*'Growth (no penalty)'!$E$24:$E$123),NA()) -> 5.6777835 | S150: =SUMPRODUCT(('Raw profile'!$I$24:$I$123>=$N150)*('Raw profile'!$I$24:$I$123<=$O150)) -> 19 | T150: =SUMPRODUCT(('Growth profile'!$I$24:$I$123>=$N150)*('Growth profile'!$I$24:$I$123<=$O150)) -> 16 | U150: =SUMPRODUCT(('Growth (no penalty)'!$I$24:$I$123>=$N150)*('Growth (no penalty)'!$I$24:$I$123<=$O150)) -> 1
M151: =N151&"-"&RIGHT(O151,2) -> 2038-40 | N151: =$U$145+12 -> 2038 | O151: =N151+2 -> 2040 | P151: =IFERROR(SUMPRODUCT(('Raw profile'!$I$24:$I$123>=$N151)*('Raw profile'!$I$24:$I$123<=$O151)*'Raw profile'!$E$24:$E$123*'Raw profile'!$S$24:$S$123)/SUMPRODUCT(('Raw profile'!$I$24:$I$123>=$N151)*('Raw profile'!$I$24:$I$123<=$O151)*'Raw profile'!$E$24:$E$123),NA()) -> 1.1166783 | Q151: =IFERROR(SUMPRODUCT(('Growth profile'!$I$24:$I$123>=$N151)*('Growth profile'!$I$24:$I$123<=$O151)*'Growth profile'!$E$24:$E$123*'Growth profile'!$S$24:$S$123)/SUMPRODUCT(('Growth profile'!$I$24:$I$123>=$N151)*('Growth profile'!$I$24:$I$123<=$O151)*'Growth profile'!$E$24:$E$123),NA()) -> 9.3049067 | R151: =IFERROR(SUMPRODUCT(('Growth (no penalty)'!$I$24:$I$123>=$N151)*('Growth (no penalty)'!$I$24:$I$123<=$O151)*'Growth (no penalty)'!$E$24:$E$123*'Growth (no penalty)'!$S$24:$S$123)/SUMPRODUCT(('Growth (no penalty)'!$I$24:$I$123>=$N151)*('Growth (no penalty)'!$I$24:$I$123<=$O151)*'Growth (no penalty)'!$E$24:$E$123),NA()) -> 5.5486849 | S151: =SUMPRODUCT(('Raw profile'!$I$24:$I$123>=$N151)*('Raw profile'!$I$24:$I$123<=$O151)) -> 13 | T151: =SUMPRODUCT(('Growth profile'!$I$24:$I$123>=$N151)*('Growth profile'!$I$24:$I$123<=$O151)) -> 9 | U151: =SUMPRODUCT(('Growth (no penalty)'!$I$24:$I$123>=$N151)*('Growth (no penalty)'!$I$24:$I$123<=$O151)) -> 6
M152: =N152&"-"&RIGHT(O152,2) -> 2041-43 | N152: =$U$145+15 -> 2041 | O152: =N152+2 -> 2043 | P152: =IFERROR(SUMPRODUCT(('Raw profile'!$I$24:$I$123>=$N152)*('Raw profile'!$I$24:$I$123<=$O152)*'Raw profile'!$E$24:$E$123*'Raw profile'!$S$24:$S$123)/SUMPRODUCT(('Raw profile'!$I$24:$I$123>=$N152)*('Raw profile'!$I$24:$I$123<=$O152)*'Raw profile'!$E$24:$E$123),NA()) -> 1.0613251 | Q152: =IFERROR(SUMPRODUCT(('Growth profile'!$I$24:$I$123>=$N152)*('Growth profile'!$I$24:$I$123<=$O152)*'Growth profile'!$E$24:$E$123*'Growth profile'!$S$24:$S$123)/SUMPRODUCT(('Growth profile'!$I$24:$I$123>=$N152)*('Growth profile'!$I$24:$I$123<=$O152)*'Growth profile'!$E$24:$E$123),NA()) -> 7.4623629 | R152: =IFERROR(SUMPRODUCT(('Growth (no penalty)'!$I$24:$I$123>=$N152)*('Growth (no penalty)'!$I$24:$I$123<=$O152)*'Growth (no penalty)'!$E$24:$E$123*'Growth (no penalty)'!$S$24:$S$123)/SUMPRODUCT(('Growth (no penalty)'!$I$24:$I$123>=$N152)*('Growth (no penalty)'!$I$24:$I$123<=$O152)*'Growth (no penalty)'!$E$24:$E$123),NA()) -> 5.4402891 | S152: =SUMPRODUCT(('Raw profile'!$I$24:$I$123>=$N152)*('Raw profile'!$I$24:$I$123<=$O152)) -> 20 | T152: =SUMPRODUCT(('Growth profile'!$I$24:$I$123>=$N152)*('Growth profile'!$I$24:$I$123<=$O152)) -> 10 | U152: =SUMPRODUCT(('Growth (no penalty)'!$I$24:$I$123>=$N152)*('Growth (no penalty)'!$I$24:$I$123<=$O152)) -> 20
M153: =N153&"-"&RIGHT(O153,2) -> 2044-46 | N153: =$U$145+18 -> 2044 | O153: =N153+2 -> 2046 | P153: =IFERROR(SUMPRODUCT(('Raw profile'!$I$24:$I$123>=$N153)*('Raw profile'!$I$24:$I$123<=$O153)*'Raw profile'!$E$24:$E$123*'Raw profile'!$S$24:$S$123)/SUMPRODUCT(('Raw profile'!$I$24:$I$123>=$N153)*('Raw profile'!$I$24:$I$123<=$O153)*'Raw profile'!$E$24:$E$123),NA()) -> #N/A | Q153: =IFERROR(SUMPRODUCT(('Growth profile'!$I$24:$I$123>=$N153)*('Growth profile'!$I$24:$I$123<=$O153)*'Growth profile'!$E$24:$E$123*'Growth profile'!$S$24:$S$123)/SUMPRODUCT(('Growth profile'!$I$24:$I$123>=$N153)*('Growth profile'!$I$24:$I$123<=$O153)*'Growth profile'!$E$24:$E$123),NA()) -> #N/A | R153: =IFERROR(SUMPRODUCT(('Growth (no penalty)'!$I$24:$I$123>=$N153)*('Growth (no penalty)'!$I$24:$I$123<=$O153)*'Growth (no penalty)'!$E$24:$E$123*'Growth (no penalty)'!$S$24:$S$123)/SUMPRODUCT(('Growth (no penalty)'!$I$24:$I$123>=$N153)*('Growth (no penalty)'!$I$24:$I$123<=$O153)*'Growth (no penalty)'!$E$24:$E$123),NA()) -> 6.5805519 | S153: =SUMPRODUCT(('Raw profile'!$I$24:$I$123>=$N153)*('Raw profile'!$I$24:$I$123<=$O153)) -> 0 | T153: =SUMPRODUCT(('Growth profile'!$I$24:$I$123>=$N153)*('Growth profile'!$I$24:$I$123<=$O153)) -> 0 | U153: =SUMPRODUCT(('Growth (no penalty)'!$I$24:$I$123>=$N153)*('Growth (no penalty)'!$I$24:$I$123<=$O153)) -> 32
M154: =N154&"-"&RIGHT(O154,2) -> 2047-49 | N154: =$U$145+21 -> 2047 | O154: =N154+2 -> 2049 | P154: =IFERROR(SUMPRODUCT(('Raw profile'!$I$24:$I$123>=$N154)*('Raw profile'!$I$24:$I$123<=$O154)*'Raw profile'!$E$24:$E$123*'Raw profile'!$S$24:$S$123)/SUMPRODUCT(('Raw profile'!$I$24:$I$123>=$N154)*('Raw profile'!$I$24:$I$123<=$O154)*'Raw profile'!$E$24:$E$123),NA()) -> #N/A | Q154: =IFERROR(SUMPRODUCT(('Growth profile'!$I$24:$I$123>=$N154)*('Growth profile'!$I$24:$I$123<=$O154)*'Growth profile'!$E$24:$E$123*'Growth profile'!$S$24:$S$123)/SUMPRODUCT(('Growth profile'!$I$24:$I$123>=$N154)*('Growth profile'!$I$24:$I$123<=$O154)*'Growth profile'!$E$24:$E$123),NA()) -> #N/A | R154: =IFERROR(SUMPRODUCT(('Growth (no penalty)'!$I$24:$I$123>=$N154)*('Growth (no penalty)'!$I$24:$I$123<=$O154)*'Growth (no penalty)'!$E$24:$E$123*'Growth (no penalty)'!$S$24:$S$123)/SUMPRODUCT(('Growth (no penalty)'!$I$24:$I$123>=$N154)*('Growth (no penalty)'!$I$24:$I$123<=$O154)*'Growth (no penalty)'!$E$24:$E$123),NA()) -> #N/A | S154: =SUMPRODUCT(('Raw profile'!$I$24:$I$123>=$N154)*('Raw profile'!$I$24:$I$123<=$O154)) -> 0 | T154: =SUMPRODUCT(('Growth profile'!$I$24:$I$123>=$N154)*('Growth profile'!$I$24:$I$123<=$O154)) -> 0 | U154: =SUMPRODUCT(('Growth (no penalty)'!$I$24:$I$123>=$N154)*('Growth (no penalty)'!$I$24:$I$123<=$O154)) -> 0
M155: =N155&"-"&RIGHT(O155,2) -> 2050-52 | N155: =$U$145+24 -> 2050 | O155: =N155+2 -> 2052 | P155: =IFERROR(SUMPRODUCT(('Raw profile'!$I$24:$I$123>=$N155)*('Raw profile'!$I$24:$I$123<=$O155)*'Raw profile'!$E$24:$E$123*'Raw profile'!$S$24:$S$123)/SUMPRODUCT(('Raw profile'!$I$24:$I$123>=$N155)*('Raw profile'!$I$24:$I$123<=$O155)*'Raw profile'!$E$24:$E$123),NA()) -> #N/A | Q155: =IFERROR(SUMPRODUCT(('Growth profile'!$I$24:$I$123>=$N155)*('Growth profile'!$I$24:$I$123<=$O155)*'Growth profile'!$E$24:$E$123*'Growth profile'!$S$24:$S$123)/SUMPRODUCT(('Growth profile'!$I$24:$I$123>=$N155)*('Growth profile'!$I$24:$I$123<=$O155)*'Growth profile'!$E$24:$E$123),NA()) -> #N/A | R155: =IFERROR(SUMPRODUCT(('Growth (no penalty)'!$I$24:$I$123>=$N155)*('Growth (no penalty)'!$I$24:$I$123<=$O155)*'Growth (no penalty)'!$E$24:$E$123*'Growth (no penalty)'!$S$24:$S$123)/SUMPRODUCT(('Growth (no penalty)'!$I$24:$I$123>=$N155)*('Growth (no penalty)'!$I$24:$I$123<=$O155)*'Growth (no penalty)'!$E$24:$E$123),NA()) -> #N/A | S155: =SUMPRODUCT(('Raw profile'!$I$24:$I$123>=$N155)*('Raw profile'!$I$24:$I$123<=$O155)) -> 0 | T155: =SUMPRODUCT(('Growth profile'!$I$24:$I$123>=$N155)*('Growth profile'!$I$24:$I$123<=$O155)) -> 0 | U155: =SUMPRODUCT(('Growth (no penalty)'!$I$24:$I$123>=$N155)*('Growth (no penalty)'!$I$24:$I$123<=$O155)) -> 0

Sheet Gantt
A1: Gantt: build (orange) and benefit years - raw vs growth vs growth with no cash penalty, 2026-2085
A2: Sorted by raw start year. Driven by the start years on the profile sheets. Red line = horizon end (2085).
E3: Build | M3: Benefit (raw) | U3: Benefit (growth) | AC3: Benefit (no cash penalty)
A5: Project | B5: Profile | C5: Start | D5: 2026 | E5: 2027 | F5: 2028 | G5: 2029 | H5: 2030 | I5: 2031 | J5: 2032 | K5: 2033 | L5: 2034 | M5: 2035 | N5: 2036 | O5: 2037 | P5: 2038 | Q5: 2039 | R5: 2040 | S5: 2041 | T5: 2042 | U5: 2043 | V5: 2044 | W5: 2045 | X5: 2046 | Y5: 2047 | Z5: 2048 | AA5: 2049 | AB5: 2050 | AC5: 2051 | AD5: 2052 | AE5: 2053 | AF5: 2054 | AG5: 2055 | AH5: 2056 | AI5: 2057 | AJ5: 2058 | AK5: 2059 | AL5: 2060 | AM5: 2061 | AN5: 2062 | AO5: 2063 | AP5: 2064 | AQ5: 2065 | AR5: 2066 | AS5: 2067 | AT5: 2068 | AU5: 2069 | AV5: 2070 | AW5: 2071 | AX5: 2072 | AY5: 2073 | AZ5: 2074 | BA5: 2075 | BB5: 2076 | BC5: 2077 | BD5: 2078 | BE5: 2079 | BF5: 2080 | BG5: 2081 | BH5: 2082 | BI5: 2083 | BJ5: 2084 | BK5: 2085
A6: ='Growth profile'!A25 -> project 4 | B6: Raw | C6: ='Raw profile'!I25 -> 2026 | D6: =IF('Raw profile'!C133>0,1,IF('Raw profile'!C236>0,2,0)) -> 1 | E6: =IF('Raw profile'!D133>0,1,IF('Raw profile'!D236>0,2,0)) -> 1 | F6: =IF('Raw profile'!E133>0,1,IF('Raw profile'!E236>0,2,0)) -> 2 | G6: =IF('Raw profile'!F133>0,1,IF('Raw profile'!F236>0,2,0)) -> 2 | H6: =IF('Raw profile'!G133>0,1,IF('Raw profile'!G236>0,2,0)) -> 2 | I6: =IF('Raw profile'!H133>0,1,IF('Raw profile'!H236>0,2,0)) -> 2 | J6: =IF('Raw profile'!I133>0,1,IF('Raw profile'!I236>0,2,0)) -> 2 | K6: =IF('Raw profile'!J133>0,1,IF('Raw profile'!J236>0,2,0)) -> 2 | ... BK6: =IF('Raw profile'!BJ133>0,1,IF('Raw profile'!BJ236>0,2,0)) -> 0
B7: Growth | C7: ='Growth profile'!I25 -> 2026 | D7: =IF('Growth profile'!C133>0,1,IF('Growth profile'!C236>0,3,0)) -> 1 | E7: =IF('Growth profile'!D133>0,1,IF('Growth profile'!D236>0,3,0)) -> 1 | F7: =IF('Growth profile'!E133>0,1,IF('Growth profile'!E236>0,3,0)) -> 3 | G7: =IF('Growth profile'!F133>0,1,IF('Growth profile'!F236>0,3,0)) -> 3 | H7: =IF('Growth profile'!G133>0,1,IF('Growth profile'!G236>0,3,0)) -> 3 | I7: =IF('Growth profile'!H133>0,1,IF('Growth profile'!H236>0,3,0)) -> 3 | J7: =IF('Growth profile'!I133>0,1,IF('Growth profile'!I236>0,3,0)) -> 3 | K7: =IF('Growth profile'!J133>0,1,IF('Growth profile'!J236>0,3,0)) -> 3 | ... BK7: =IF('Growth profile'!BJ133>0,1,IF('Growth profile'!BJ236>0,3,0)) -> 0
B8: No penalty | C8: ='Growth (no penalty)'!I25 -> 2026 | D8: =IF('Growth (no penalty)'!C133>0,1,IF('Growth (no penalty)'!C236>0,4,0)) -> 1 | E8: =IF('Growth (no penalty)'!D133>0,1,IF('Growth (no penalty)'!D236>0,4,0)) -> 1 | F8: =IF('Growth (no penalty)'!E133>0,1,IF('Growth (no penalty)'!E236>0,4,0)) -> 4 | G8: =IF('Growth (no penalty)'!F133>0,1,IF('Growth (no penalty)'!F236>0,4,0)) -> 4 | H8: =IF('Growth (no penalty)'!G133>0,1,IF('Growth (no penalty)'!G236>0,4,0)) -> 4 | I8: =IF('Growth (no penalty)'!H133>0,1,IF('Growth (no penalty)'!H236>0,4,0)) -> 4 | J8: =IF('Growth (no penalty)'!I133>0,1,IF('Growth (no penalty)'!I236>0,4,0)) -> 4 | K8: =IF('Growth (no penalty)'!J133>0,1,IF('Growth (no penalty)'!J236>0,4,0)) -> 4 | ... BK8: =IF('Growth (no penalty)'!BJ133>0,1,IF('Growth (no penalty)'!BJ236>0,4,0)) -> 0
A9: ='Growth profile'!A33 -> project 22 | B9: Raw | C9: ='Raw profile'!I33 -> 2026 | D9: =IF('Raw profile'!C141>0,1,IF('Raw profile'!C244>0,2,0)) -> 1 | E9: =IF('Raw profile'!D141>0,1,IF('Raw profile'!D244>0,2,0)) -> 1 | F9: =IF('Raw profile'!E141>0,1,IF('Raw profile'!E244>0,2,0)) -> 2 | G9: =IF('Raw profile'!F141>0,1,IF('Raw profile'!F244>0,2,0)) -> 2 | H9: =IF('Raw profile'!G141>0,1,IF('Raw profile'!G244>0,2,0)) -> 2 | I9: =IF('Raw profile'!H141>0,1,IF('Raw profile'!H244>0,2,0)) -> 2 | J9: =IF('Raw profile'!I141>0,1,IF('Raw profile'!I244>0,2,0)) -> 2 | K9: =IF('Raw profile'!J141>0,1,IF('Raw profile'!J244>0,2,0)) -> 2 | ... BK9: =IF('Raw profile'!BJ141>0,1,IF('Raw profile'!BJ244>0,2,0)) -> 0
B10: Growth | C10: ='Growth profile'!I33 -> 2026 | D10: =IF('Growth profile'!C141>0,1,IF('Growth profile'!C244>0,3,0)) -> 1 | E10: =IF('Growth profile'!D141>0,1,IF('Growth profile'!D244>0,3,0)) -> 1 | F10: =IF('Growth profile'!E141>0,1,IF('Growth profile'!E244>0,3,0)) -> 3 | G10: =IF('Growth profile'!F141>0,1,IF('Growth profile'!F244>0,3,0)) -> 3 | H10: =IF('Growth profile'!G141>0,1,IF('Growth profile'!G244>0,3,0)) -> 3 | I10: =IF('Growth profile'!H141>0,1,IF('Growth profile'!H244>0,3,0)) -> 3 | J10: =IF('Growth profile'!I141>0,1,IF('Growth profile'!I244>0,3,0)) -> 3 | K10: =IF('Growth profile'!J141>0,1,IF('Growth profile'!J244>0,3,0)) -> 3 | ... BK10: =IF('Growth profile'!BJ141>0,1,IF('Growth profile'!BJ244>0,3,0)) -> 0
B11: No penalty | C11: ='Growth (no penalty)'!I33 -> 2026 | D11: =IF('Growth (no penalty)'!C141>0,1,IF('Growth (no penalty)'!C244>0,4,0)) -> 1 | E11: =IF('Growth (no penalty)'!D141>0,1,IF('Growth (no penalty)'!D244>0,4,0)) -> 1 | F11: =IF('Growth (no penalty)'!E141>0,1,IF('Growth (no penalty)'!E244>0,4,0)) -> 4 | G11: =IF('Growth (no penalty)'!F141>0,1,IF('Growth (no penalty)'!F244>0,4,0)) -> 4 | H11: =IF('Growth (no penalty)'!G141>0,1,IF('Growth (no penalty)'!G244>0,4,0)) -> 4 | I11: =IF('Growth (no penalty)'!H141>0,1,IF('Growth (no penalty)'!H244>0,4,0)) -> 4 | J11: =IF('Growth (no penalty)'!I141>0,1,IF('Growth (no penalty)'!I244>0,4,0)) -> 4 | K11: =IF('Growth (no penalty)'!J141>0,1,IF('Growth (no penalty)'!J244>0,4,0)) -> 4 | ... BK11: =IF('Growth (no penalty)'!BJ141>0,1,IF('Growth (no penalty)'!BJ244>0,4,0)) -> 0
A12: ='Growth profile'!A36 -> project 26 | B12: Raw | C12: ='Raw profile'!I36 -> 2026 | D12: =IF('Raw profile'!C144>0,1,IF('Raw profile'!C247>0,2,0)) -> 1 | E12: =IF('Raw profile'!D144>0,1,IF('Raw profile'!D247>0,2,0)) -> 2 | F12: =IF('Raw profile'!E144>0,1,IF('Raw profile'!E247>0,2,0)) -> 2 | G12: =IF('Raw profile'!F144>0,1,IF('Raw profile'!F247>0,2,0)) -> 2 | H12: =IF('Raw profile'!G144>0,1,IF('Raw profile'!G247>0,2,0)) -> 2 | I12: =IF('Raw profile'!H144>0,1,IF('Raw profile'!H247>0,2,0)) -> 2 | J12: =IF('Raw profile'!I144>0,1,IF('Raw profile'!I247>0,2,0)) -> 2 | K12: =IF('Raw profile'!J144>0,1,IF('Raw profile'!J247>0,2,0)) -> 2 | ... BK12: =IF('Raw profile'!BJ144>0,1,IF('Raw profile'!BJ247>0,2,0)) -> 0
B13: Growth | C13: ='Growth profile'!I36 -> 2026 | D13: =IF('Growth profile'!C144>0,1,IF('Growth profile'!C247>0,3,0)) -> 1 | E13: =IF('Growth profile'!D144>0,1,IF('Growth profile'!D247>0,3,0)) -> 3 | F13: =IF('Growth profile'!E144>0,1,IF('Growth profile'!E247>0,3,0)) -> 3 | G13: =IF('Growth profile'!F144>0,1,IF('Growth profile'!F247>0,3,0)) -> 3 | H13: =IF('Growth profile'!G144>0,1,IF('Growth profile'!G247>0,3,0)) -> 3 | I13: =IF('Growth profile'!H144>0,1,IF('Growth profile'!H247>0,3,0)) -> 3 | J13: =IF('Growth profile'!I144>0,1,IF('Growth profile'!I247>0,3,0)) -> 3 | K13: =IF('Growth profile'!J144>0,1,IF('Growth profile'!J247>0,3,0)) -> 3 | ... BK13: =IF('Growth profile'!BJ144>0,1,IF('Growth profile'!BJ247>0,3,0)) -> 0
B14: No penalty | C14: ='Growth (no penalty)'!I36 -> 2026 | D14: =IF('Growth (no penalty)'!C144>0,1,IF('Growth (no penalty)'!C247>0,4,0)) -> 1 | E14: =IF('Growth (no penalty)'!D144>0,1,IF('Growth (no penalty)'!D247>0,4,0)) -> 4 | F14: =IF('Growth (no penalty)'!E144>0,1,IF('Growth (no penalty)'!E247>0,4,0)) -> 4 | G14: =IF('Growth (no penalty)'!F144>0,1,IF('Growth (no penalty)'!F247>0,4,0)) -> 4 | H14: =IF('Growth (no penalty)'!G144>0,1,IF('Growth (no penalty)'!G247>0,4,0)) -> 4 | I14: =IF('Growth (no penalty)'!H144>0,1,IF('Growth (no penalty)'!H247>0,4,0)) -> 4 | J14: =IF('Growth (no penalty)'!I144>0,1,IF('Growth (no penalty)'!I247>0,4,0)) -> 4 | K14: =IF('Growth (no penalty)'!J144>0,1,IF('Growth (no penalty)'!J247>0,4,0)) -> 4 | ... BK14: =IF('Growth (no penalty)'!BJ144>0,1,IF('Growth (no penalty)'!BJ247>0,4,0)) -> 0
A15: ='Growth profile'!A38 -> project 28 | B15: Raw | C15: ='Raw profile'!I38 -> 2026 | D15: =IF('Raw profile'!C146>0,1,IF('Raw profile'!C249>0,2,0)) -> 1 | E15: =IF('Raw profile'!D146>0,1,IF('Raw profile'!D249>0,2,0)) -> 1 | F15: =IF('Raw profile'!E146>0,1,IF('Raw profile'!E249>0,2,0)) -> 2 | G15: =IF('Raw profile'!F146>0,1,IF('Raw profile'!F249>0,2,0)) -> 2 | H15: =IF('Raw profile'!G146>0,1,IF('Raw profile'!G249>0,2,0)) -> 2 | I15: =IF('Raw profile'!H146>0,1,IF('Raw profile'!H249>0,2,0)) -> 2 | J15: =IF('Raw profile'!I146>0,1,IF('Raw profile'!I249>0,2,0)) -> 2 | K15: =IF('Raw profile'!J146>0,1,IF('Raw profile'!J249>0,2,0)) -> 2 | ... BK15: =IF('Raw profile'!BJ146>0,1,IF('Raw profile'!BJ249>0,2,0)) -> 0
B16: Growth | C16: ='Growth profile'!I38 -> 2026 | D16: =IF('Growth profile'!C146>0,1,IF('Growth profile'!C249>0,3,0)) -> 1 | E16: =IF('Growth profile'!D146>0,1,IF('Growth profile'!D249>0,3,0)) -> 1 | F16: =IF('Growth profile'!E146>0,1,IF('Growth profile'!E249>0,3,0)) -> 3 | G16: =IF('Growth profile'!F146>0,1,IF('Growth profile'!F249>0,3,0)) -> 3 | H16: =IF('Growth profile'!G146>0,1,IF('Growth profile'!G249>0,3,0)) -> 3 | I16: =IF('Growth profile'!H146>0,1,IF('Growth profile'!H249>0,3,0)) -> 3 | J16: =IF('Growth profile'!I146>0,1,IF('Growth profile'!I249>0,3,0)) -> 3 | K16: =IF('Growth profile'!J146>0,1,IF('Growth profile'!J249>0,3,0)) -> 3 | ... BK16: =IF('Growth profile'!BJ146>0,1,IF('Growth profile'!BJ249>0,3,0)) -> 0
B17: No penalty | C17: ='Growth (no penalty)'!I38 -> 2026 | D17: =IF('Growth (no penalty)'!C146>0,1,IF('Growth (no penalty)'!C249>0,4,0)) -> 1 | E17: =IF('Growth (no penalty)'!D146>0,1,IF('Growth (no penalty)'!D249>0,4,0)) -> 1 | F17: =IF('Growth (no penalty)'!E146>0,1,IF('Growth (no penalty)'!E249>0,4,0)) -> 4 | G17: =IF('Growth (no penalty)'!F146>0,1,IF('Growth (no penalty)'!F249>0,4,0)) -> 4 | H17: =IF('Growth (no penalty)'!G146>0,1,IF('Growth (no penalty)'!G249>0,4,0)) -> 4 | I17: =IF('Growth (no penalty)'!H146>0,1,IF('Growth (no penalty)'!H249>0,4,0)) -> 4 | J17: =IF('Growth (no penalty)'!I146>0,1,IF('Growth (no penalty)'!I249>0,4,0)) -> 4 | K17: =IF('Growth (no penalty)'!J146>0,1,IF('Growth (no penalty)'!J249>0,4,0)) -> 4 | ... BK17: =IF('Growth (no penalty)'!BJ146>0,1,IF('Growth (no penalty)'!BJ249>0,4,0)) -> 0
A18: ='Growth profile'!A40 -> project 32 | B18: Raw | C18: ='Raw profile'!I40 -> 2026 | D18: =IF('Raw profile'!C148>0,1,IF('Raw profile'!C251>0,2,0)) -> 1 | E18: =IF('Raw profile'!D148>0,1,IF('Raw profile'!D251>0,2,0)) -> 1 | F18: =IF('Raw profile'!E148>0,1,IF('Raw profile'!E251>0,2,0)) -> 1 | G18: =IF('Raw profile'!F148>0,1,IF('Raw profile'!F251>0,2,0)) -> 2 | H18: =IF('Raw profile'!G148>0,1,IF('Raw profile'!G251>0,2,0)) -> 2 | I18: =IF('Raw profile'!H148>0,1,IF('Raw profile'!H251>0,2,0)) -> 2 | J18: =IF('Raw profile'!I148>0,1,IF('Raw profile'!I251>0,2,0)) -> 2 | K18: =IF('Raw profile'!J148>0,1,IF('Raw profile'!J251>0,2,0)) -> 2 | ... BK18: =IF('Raw profile'!BJ148>0,1,IF('Raw profile'!BJ251>0,2,0)) -> 0
B19: Growth | C19: ='Growth profile'!I40 -> 2026 | D19: =IF('Growth profile'!C148>0,1,IF('Growth profile'!C251>0,3,0)) -> 1 | E19: =IF('Growth profile'!D148>0,1,IF('Growth profile'!D251>0,3,0)) -> 1 | F19: =IF('Growth profile'!E148>0,1,IF('Growth profile'!E251>0,3,0)) -> 1 | G19: =IF('Growth profile'!F148>0,1,IF('Growth profile'!F251>0,3,0)) -> 3 | H19: =IF('Growth profile'!G148>0,1,IF('Growth profile'!G251>0,3,0)) -> 3 | I19: =IF('Growth profile'!H148>0,1,IF('Growth profile'!H251>0,3,0)) -> 3 | J19: =IF('Growth profile'!I148>0,1,IF('Growth profile'!I251>0,3,0)) -> 3 | K19: =IF('Growth profile'!J148>0,1,IF('Growth profile'!J251>0,3,0)) -> 3 | ... BK19: =IF('Growth profile'!BJ148>0,1,IF('Growth profile'!BJ251>0,3,0)) -> 0
B20: No penalty | C20: ='Growth (no penalty)'!I40 -> 2026 | D20: =IF('Growth (no penalty)'!C148>0,1,IF('Growth (no penalty)'!C251>0,4,0)) -> 1 | E20: =IF('Growth (no penalty)'!D148>0,1,IF('Growth (no penalty)'!D251>0,4,0)) -> 1 | F20: =IF('Growth (no penalty)'!E148>0,1,IF('Growth (no penalty)'!E251>0,4,0)) -> 1 | G20: =IF('Growth (no penalty)'!F148>0,1,IF('Growth (no penalty)'!F251>0,4,0)) -> 4 | H20: =IF('Growth (no penalty)'!G148>0,1,IF('Growth (no penalty)'!G251>0,4,0)) -> 4 | I20: =IF('Growth (no penalty)'!H148>0,1,IF('Growth (no penalty)'!H251>0,4,0)) -> 4 | J20: =IF('Growth (no penalty)'!I148>0,1,IF('Growth (no penalty)'!I251>0,4,0)) -> 4 | K20: =IF('Growth (no penalty)'!J148>0,1,IF('Growth (no penalty)'!J251>0,4,0)) -> 4 | ... BK20: =IF('Growth (no penalty)'!BJ148>0,1,IF('Growth (no penalty)'!BJ251>0,4,0)) -> 0
A21: ='Growth profile'!A59 -> project 64 | B21: Raw | C21: ='Raw profile'!I59 -> 2026 | D21: =IF('Raw profile'!C167>0,1,IF('Raw profile'!C270>0,2,0)) -> 1 | E21: =IF('Raw profile'!D167>0,1,IF('Raw profile'!D270>0,2,0)) -> 1 | F21: =IF('Raw profile'!E167>0,1,IF('Raw profile'!E270>0,2,0)) -> 2 | G21: =IF('Raw profile'!F167>0,1,IF('Raw profile'!F270>0,2,0)) -> 2 | H21: =IF('Raw profile'!G167>0,1,IF('Raw profile'!G270>0,2,0)) -> 2 | I21: =IF('Raw profile'!H167>0,1,IF('Raw profile'!H270>0,2,0)) -> 2 | J21: =IF('Raw profile'!I167>0,1,IF('Raw profile'!I270>0,2,0)) -> 2 | K21: =IF('Raw profile'!J167>0,1,IF('Raw profile'!J270>0,2,0)) -> 2 | ... BK21: =IF('Raw profile'!BJ167>0,1,IF('Raw profile'!BJ270>0,2,0)) -> 0
B22: Growth | C22: ='Growth profile'!I59 -> 2026 | D22: =IF('Growth profile'!C167>0,1,IF('Growth profile'!C270>0,3,0)) -> 1 | E22: =IF('Growth profile'!D167>0,1,IF('Growth profile'!D270>0,3,0)) -> 1 | F22: =IF('Growth profile'!E167>0,1,IF('Growth profile'!E270>0,3,0)) -> 3 | G22: =IF('Growth profile'!F167>0,1,IF('Growth profile'!F270>0,3,0)) -> 3 | H22: =IF('Growth profile'!G167>0,1,IF('Growth profile'!G270>0,3,0)) -> 3 | I22: =IF('Growth profile'!H167>0,1,IF('Growth profile'!H270>0,3,0)) -> 3 | J22: =IF('Growth profile'!I167>0,1,IF('Growth profile'!I270>0,3,0)) -> 3 | K22: =IF('Growth profile'!J167>0,1,IF('Growth profile'!J270>0,3,0)) -> 3 | ... BK22: =IF('Growth profile'!BJ167>0,1,IF('Growth profile'!BJ270>0,3,0)) -> 0
B23: No penalty | C23: ='Growth (no penalty)'!I59 -> 2026 | D23: =IF('Growth (no penalty)'!C167>0,1,IF('Growth (no penalty)'!C270>0,4,0)) -> 1 | E23: =IF('Growth (no penalty)'!D167>0,1,IF('Growth (no penalty)'!D270>0,4,0)) -> 1 | F23: =IF('Growth (no penalty)'!E167>0,1,IF('Growth (no penalty)'!E270>0,4,0)) -> 4 | G23: =IF('Growth (no penalty)'!F167>0,1,IF('Growth (no penalty)'!F270>0,4,0)) -> 4 | H23: =IF('Growth (no penalty)'!G167>0,1,IF('Growth (no penalty)'!G270>0,4,0)) -> 4 | I23: =IF('Growth (no penalty)'!H167>0,1,IF('Growth (no penalty)'!H270>0,4,0)) -> 4 | J23: =IF('Growth (no penalty)'!I167>0,1,IF('Growth (no penalty)'!I270>0,4,0)) -> 4 | K23: =IF('Growth (no penalty)'!J167>0,1,IF('Growth (no penalty)'!J270>0,4,0)) -> 4 | ... BK23: =IF('Growth (no penalty)'!BJ167>0,1,IF('Growth (no penalty)'!BJ270>0,4,0)) -> 0
A24: ='Growth profile'!A74 -> project 106 | B24: Raw | C24: ='Raw profile'!I74 -> 2026 | D24: =IF('Raw profile'!C182>0,1,IF('Raw profile'!C285>0,2,0)) -> 1 | E24: =IF('Raw profile'!D182>0,1,IF('Raw profile'!D285>0,2,0)) -> 1 | F24: =IF('Raw profile'!E182>0,1,IF('Raw profile'!E285>0,2,0)) -> 1 | G24: =IF('Raw profile'!F182>0,1,IF('Raw profile'!F285>0,2,0)) -> 1 | H24: =IF('Raw profile'!G182>0,1,IF('Raw profile'!G285>0,2,0)) -> 1 | I24: =IF('Raw profile'!H182>0,1,IF('Raw profile'!H285>0,2,0)) -> 1 | J24: =IF('Raw profile'!I182>0,1,IF('Raw profile'!I285>0,2,0)) -> 1 | K24: =IF('Raw profile'!J182>0,1,IF('Raw profile'!J285>0,2,0)) -> 1 | ... BK24: =IF('Raw profile'!BJ182>0,1,IF('Raw profile'!BJ285>0,2,0)) -> 0
B25: Growth | C25: ='Growth profile'!I74 -> 2026 | D25: =IF('Growth profile'!C182>0,1,IF('Growth profile'!C285>0,3,0)) -> 1 | E25: =IF('Growth profile'!D182>0,1,IF('Growth profile'!D285>0,3,0)) -> 1 | F25: =IF('Growth profile'!E182>0,1,IF('Growth profile'!E285>0,3,0)) -> 1 | G25: =IF('Growth profile'!F182>0,1,IF('Growth profile'!F285>0,3,0)) -> 1 | H25: =IF('Growth profile'!G182>0,1,IF('Growth profile'!G285>0,3,0)) -> 1 | I25: =IF('Growth profile'!H182>0,1,IF('Growth profile'!H285>0,3,0)) -> 1 | J25: =IF('Growth profile'!I182>0,1,IF('Growth profile'!I285>0,3,0)) -> 1 | K25: =IF('Growth profile'!J182>0,1,IF('Growth profile'!J285>0,3,0)) -> 1 | ... BK25: =IF('Growth profile'!BJ182>0,1,IF('Growth profile'!BJ285>0,3,0)) -> 0
B26: No penalty | C26: ='Growth (no penalty)'!I74 -> 2026 | D26: =IF('Growth (no penalty)'!C182>0,1,IF('Growth (no penalty)'!C285>0,4,0)) -> 1 | E26: =IF('Growth (no penalty)'!D182>0,1,IF('Growth (no penalty)'!D285>0,4,0)) -> 1 | F26: =IF('Growth (no penalty)'!E182>0,1,IF('Growth (no penalty)'!E285>0,4,0)) -> 1 | G26: =IF('Growth (no penalty)'!F182>0,1,IF('Growth (no penalty)'!F285>0,4,0)) -> 1 | H26: =IF('Growth (no penalty)'!G182>0,1,IF('Growth (no penalty)'!G285>0,4,0)) -> 1 | I26: =IF('Growth (no penalty)'!H182>0,1,IF('Growth (no penalty)'!H285>0,4,0)) -> 1 | J26: =IF('Growth (no penalty)'!I182>0,1,IF('Growth (no penalty)'!I285>0,4,0)) -> 1 | K26: =IF('Growth (no penalty)'!J182>0,1,IF('Growth (no penalty)'!J285>0,4,0)) -> 1 | ... BK26: =IF('Growth (no penalty)'!BJ182>0,1,IF('Growth (no penalty)'!BJ285>0,4,0)) -> 0
A27: ='Growth profile'!A79 -> project 116 | B27: Raw | C27: ='Raw profile'!I79 -> 2026 | D27: =IF('Raw profile'!C187>0,1,IF('Raw profile'!C290>0,2,0)) -> 1 | E27: =IF('Raw profile'!D187>0,1,IF('Raw profile'!D290>0,2,0)) -> 1 | F27: =IF('Raw profile'!E187>0,1,IF('Raw profile'!E290>0,2,0)) -> 1 | G27: =IF('Raw profile'!F187>0,1,IF('Raw profile'!F290>0,2,0)) -> 1 | H27: =IF('Raw profile'!G187>0,1,IF('Raw profile'!G290>0,2,0)) -> 1 | I27: =IF('Raw profile'!H187>0,1,IF('Raw profile'!H290>0,2,0)) -> 2 | J27: =IF('Raw profile'!I187>0,1,IF('Raw profile'!I290>0,2,0)) -> 2 | K27: =IF('Raw profile'!J187>0,1,IF('Raw profile'!J290>0,2,0)) -> 2 | ... BK27: =IF('Raw profile'!BJ187>0,1,IF('Raw profile'!BJ290>0,2,0)) -> 0
B28: Growth | C28: ='Growth profile'!I79 -> 2026 | D28: =IF('Growth profile'!C187>0,1,IF('Growth profile'!C290>0,3,0)) -> 1 | E28: =IF('Growth profile'!D187>0,1,IF('Growth profile'!D290>0,3,0)) -> 1 | F28: =IF('Growth profile'!E187>0,1,IF('Growth profile'!E290>0,3,0)) -> 1 | G28: =IF('Growth profile'!F187>0,1,IF('Growth profile'!F290>0,3,0)) -> 1 | H28: =IF('Growth profile'!G187>0,1,IF('Growth profile'!G290>0,3,0)) -> 1 | I28: =IF('Growth profile'!H187>0,1,IF('Growth profile'!H290>0,3,0)) -> 3 | J28: =IF('Growth profile'!I187>0,1,IF('Growth profile'!I290>0,3,0)) -> 3 | K28: =IF('Growth profile'!J187>0,1,IF('Growth profile'!J290>0,3,0)) -> 3 | ... BK28: =IF('Growth profile'!BJ187>0,1,IF('Growth profile'!BJ290>0,3,0)) -> 0
B29: No penalty | C29: ='Growth (no penalty)'!I79 -> 2026 | D29: =IF('Growth (no penalty)'!C187>0,1,IF('Growth (no penalty)'!C290>0,4,0)) -> 1 | E29: =IF('Growth (no penalty)'!D187>0,1,IF('Growth (no penalty)'!D290>0,4,0)) -> 1 | F29: =IF('Growth (no penalty)'!E187>0,1,IF('Growth (no penalty)'!E290>0,4,0)) -> 1 | G29: =IF('Growth (no penalty)'!F187>0,1,IF('Growth (no penalty)'!F290>0,4,0)) -> 1 | H29: =IF('Growth (no penalty)'!G187>0,1,IF('Growth (no penalty)'!G290>0,4,0)) -> 1 | I29: =IF('Growth (no penalty)'!H187>0,1,IF('Growth (no penalty)'!H290>0,4,0)) -> 4 | J29: =IF('Growth (no penalty)'!I187>0,1,IF('Growth (no penalty)'!I290>0,4,0)) -> 4 | K29: =IF('Growth (no penalty)'!J187>0,1,IF('Growth (no penalty)'!J290>0,4,0)) -> 4 | ... BK29: =IF('Growth (no penalty)'!BJ187>0,1,IF('Growth (no penalty)'!BJ290>0,4,0)) -> 0
A30: ='Growth profile'!A81 -> project 120 | B30: Raw | C30: ='Raw profile'!I81 -> 2026 | D30: =IF('Raw profile'!C189>0,1,IF('Raw profile'!C292>0,2,0)) -> 1 | E30: =IF('Raw profile'!D189>0,1,IF('Raw profile'!D292>0,2,0)) -> 1 | F30: =IF('Raw profile'!E189>0,1,IF('Raw profile'!E292>0,2,0)) -> 1 | G30: =IF('Raw profile'!F189>0,1,IF('Raw profile'!F292>0,2,0)) -> 1 | H30: =IF('Raw profile'!G189>0,1,IF('Raw profile'!G292>0,2,0)) -> 1 | I30: =IF('Raw profile'!H189>0,1,IF('Raw profile'!H292>0,2,0)) -> 1 | J30: =IF('Raw profile'!I189>0,1,IF('Raw profile'!I292>0,2,0)) -> 2 | K30: =IF('Raw profile'!J189>0,1,IF('Raw profile'!J292>0,2,0)) -> 2 | ... BK30: =IF('Raw profile'!BJ189>0,1,IF('Raw profile'!BJ292>0,2,0)) -> 0
B31: Growth | C31: ='Growth profile'!I81 -> 2026 | D31: =IF('Growth profile'!C189>0,1,IF('Growth profile'!C292>0,3,0)) -> 1 | E31: =IF('Growth profile'!D189>0,1,IF('Growth profile'!D292>0,3,0)) -> 1 | F31: =IF('Growth profile'!E189>0,1,IF('Growth profile'!E292>0,3,0)) -> 1 | G31: =IF('Growth profile'!F189>0,1,IF('Growth profile'!F292>0,3,0)) -> 1 | H31: =IF('Growth profile'!G189>0,1,IF('Growth profile'!G292>0,3,0)) -> 1 | I31: =IF('Growth profile'!H189>0,1,IF('Growth profile'!H292>0,3,0)) -> 1 | J31: =IF('Growth profile'!I189>0,1,IF('Growth profile'!I292>0,3,0)) -> 3 | K31: =IF('Growth profile'!J189>0,1,IF('Growth profile'!J292>0,3,0)) -> 3 | ... BK31: =IF('Growth profile'!BJ189>0,1,IF('Growth profile'!BJ292>0,3,0)) -> 0
B32: No penalty | C32: ='Growth (no penalty)'!I81 -> 2026 | D32: =IF('Growth (no penalty)'!C189>0,1,IF('Growth (no penalty)'!C292>0,4,0)) -> 1 | E32: =IF('Growth (no penalty)'!D189>0,1,IF('Growth (no penalty)'!D292>0,4,0)) -> 1 | F32: =IF('Growth (no penalty)'!E189>0,1,IF('Growth (no penalty)'!E292>0,4,0)) -> 1 | G32: =IF('Growth (no penalty)'!F189>0,1,IF('Growth (no penalty)'!F292>0,4,0)) -> 1 | H32: =IF('Growth (no penalty)'!G189>0,1,IF('Growth (no penalty)'!G292>0,4,0)) -> 1 | I32: =IF('Growth (no penalty)'!H189>0,1,IF('Growth (no penalty)'!H292>0,4,0)) -> 1 | J32: =IF('Growth (no penalty)'!I189>0,1,IF('Growth (no penalty)'!I292>0,4,0)) -> 4 | K32: =IF('Growth (no penalty)'!J189>0,1,IF('Growth (no penalty)'!J292>0,4,0)) -> 4 | ... BK32: =IF('Growth (no penalty)'!BJ189>0,1,IF('Growth (no penalty)'!BJ292>0,4,0)) -> 0
A33: ='Growth profile'!A97 -> project 153 | B33: Raw | C33: ='Raw profile'!I97 -> 2026 | D33: =IF('Raw profile'!C205>0,1,IF('Raw profile'!C308>0,2,0)) -> 1 | E33: =IF('Raw profile'!D205>0,1,IF('Raw profile'!D308>0,2,0)) -> 1 | F33: =IF('Raw profile'!E205>0,1,IF('Raw profile'!E308>0,2,0)) -> 2 | G33: =IF('Raw profile'!F205>0,1,IF('Raw profile'!F308>0,2,0)) -> 2 | H33: =IF('Raw profile'!G205>0,1,IF('Raw profile'!G308>0,2,0)) -> 2 | I33: =IF('Raw profile'!H205>0,1,IF('Raw profile'!H308>0,2,0)) -> 2 | J33: =IF('Raw profile'!I205>0,1,IF('Raw profile'!I308>0,2,0)) -> 2 | K33: =IF('Raw profile'!J205>0,1,IF('Raw profile'!J308>0,2,0)) -> 2 | ... BK33: =IF('Raw profile'!BJ205>0,1,IF('Raw profile'!BJ308>0,2,0)) -> 0
B34: Growth | C34: ='Growth profile'!I97 -> 2026 | D34: =IF('Growth profile'!C205>0,1,IF('Growth profile'!C308>0,3,0)) -> 1 | E34: =IF('Growth profile'!D205>0,1,IF('Growth profile'!D308>0,3,0)) -> 1 | F34: =IF('Growth profile'!E205>0,1,IF('Growth profile'!E308>0,3,0)) -> 3 | G34: =IF('Growth profile'!F205>0,1,IF('Growth profile'!F308>0,3,0)) -> 3 | H34: =IF('Growth profile'!G205>0,1,IF('Growth profile'!G308>0,3,0)) -> 3 | I34: =IF('Growth profile'!H205>0,1,IF('Growth profile'!H308>0,3,0)) -> 3 | J34: =IF('Growth profile'!I205>0,1,IF('Growth profile'!I308>0,3,0)) -> 3 | K34: =IF('Growth profile'!J205>0,1,IF('Growth profile'!J308>0,3,0)) -> 3 | ... BK34: =IF('Growth profile'!BJ205>0,1,IF('Growth profile'!BJ308>0,3,0)) -> 0
B35: No penalty | C35: ='Growth (no penalty)'!I97 -> 2026 | D35: =IF('Growth (no penalty)'!C205>0,1,IF('Growth (no penalty)'!C308>0,4,0)) -> 1 | E35: =IF('Growth (no penalty)'!D205>0,1,IF('Growth (no penalty)'!D308>0,4,0)) -> 1 | F35: =IF('Growth (no penalty)'!E205>0,1,IF('Growth (no penalty)'!E308>0,4,0)) -> 4 | G35: =IF('Growth (no penalty)'!F205>0,1,IF('Growth (no penalty)'!F308>0,4,0)) -> 4 | H35: =IF('Growth (no penalty)'!G205>0,1,IF('Growth (no penalty)'!G308>0,4,0)) -> 4 | I35: =IF('Growth (no penalty)'!H205>0,1,IF('Growth (no penalty)'!H308>0,4,0)) -> 4 | J35: =IF('Growth (no penalty)'!I205>0,1,IF('Growth (no penalty)'!I308>0,4,0)) -> 4 | K35: =IF('Growth (no penalty)'!J205>0,1,IF('Growth (no penalty)'!J308>0,4,0)) -> 4 | ... BK35: =IF('Growth (no penalty)'!BJ205>0,1,IF('Growth (no penalty)'!BJ308>0,4,0)) -> 0
A36: ='Growth profile'!A121 -> project 211 | B36: Raw | C36: ='Raw profile'!I121 -> 2026 | D36: =IF('Raw profile'!C229>0,1,IF('Raw profile'!C332>0,2,0)) -> 1 | E36: =IF('Raw profile'!D229>0,1,IF('Raw profile'!D332>0,2,0)) -> 2 | F36: =IF('Raw profile'!E229>0,1,IF('Raw profile'!E332>0,2,0)) -> 2 | G36: =IF('Raw profile'!F229>0,1,IF('Raw profile'!F332>0,2,0)) -> 2 | H36: =IF('Raw profile'!G229>0,1,IF('Raw profile'!G332>0,2,0)) -> 2 | I36: =IF('Raw profile'!H229>0,1,IF('Raw profile'!H332>0,2,0)) -> 2 | J36: =IF('Raw profile'!I229>0,1,IF('Raw profile'!I332>0,2,0)) -> 2 | K36: =IF('Raw profile'!J229>0,1,IF('Raw profile'!J332>0,2,0)) -> 2 | ... BK36: =IF('Raw profile'!BJ229>0,1,IF('Raw profile'!BJ332>0,2,0)) -> 0
B37: Growth | C37: ='Growth profile'!I121 -> 2026 | D37: =IF('Growth profile'!C229>0,1,IF('Growth profile'!C332>0,3,0)) -> 1 | E37: =IF('Growth profile'!D229>0,1,IF('Growth profile'!D332>0,3,0)) -> 3 | F37: =IF('Growth profile'!E229>0,1,IF('Growth profile'!E332>0,3,0)) -> 3 | G37: =IF('Growth profile'!F229>0,1,IF('Growth profile'!F332>0,3,0)) -> 3 | H37: =IF('Growth profile'!G229>0,1,IF('Growth profile'!G332>0,3,0)) -> 3 | I37: =IF('Growth profile'!H229>0,1,IF('Growth profile'!H332>0,3,0)) -> 3 | J37: =IF('Growth profile'!I229>0,1,IF('Growth profile'!I332>0,3,0)) -> 3 | K37: =IF('Growth profile'!J229>0,1,IF('Growth profile'!J332>0,3,0)) -> 3 | ... BK37: =IF('Growth profile'!BJ229>0,1,IF('Growth profile'!BJ332>0,3,0)) -> 0
B38: No penalty | C38: ='Growth (no penalty)'!I121 -> 2026 | D38: =IF('Growth (no penalty)'!C229>0,1,IF('Growth (no penalty)'!C332>0,4,0)) -> 1 | E38: =IF('Growth (no penalty)'!D229>0,1,IF('Growth (no penalty)'!D332>0,4,0)) -> 4 | F38: =IF('Growth (no penalty)'!E229>0,1,IF('Growth (no penalty)'!E332>0,4,0)) -> 4 | G38: =IF('Growth (no penalty)'!F229>0,1,IF('Growth (no penalty)'!F332>0,4,0)) -> 4 | H38: =IF('Growth (no penalty)'!G229>0,1,IF('Growth (no penalty)'!G332>0,4,0)) -> 4 | I38: =IF('Growth (no penalty)'!H229>0,1,IF('Growth (no penalty)'!H332>0,4,0)) -> 4 | J38: =IF('Growth (no penalty)'!I229>0,1,IF('Growth (no penalty)'!I332>0,4,0)) -> 4 | K38: =IF('Growth (no penalty)'!J229>0,1,IF('Growth (no penalty)'!J332>0,4,0)) -> 4 | ... BK38: =IF('Growth (no penalty)'!BJ229>0,1,IF('Growth (no penalty)'!BJ332>0,4,0)) -> 0
A39: ='Growth profile'!A49 -> project 44 | B39: Raw | C39: ='Raw profile'!I49 -> 2026 | D39: =IF('Raw profile'!C157>0,1,IF('Raw profile'!C260>0,2,0)) -> 1 | E39: =IF('Raw profile'!D157>0,1,IF('Raw profile'!D260>0,2,0)) -> 2 | F39: =IF('Raw profile'!E157>0,1,IF('Raw profile'!E260>0,2,0)) -> 2 | G39: =IF('Raw profile'!F157>0,1,IF('Raw profile'!F260>0,2,0)) -> 2 | H39: =IF('Raw profile'!G157>0,1,IF('Raw profile'!G260>0,2,0)) -> 2 | I39: =IF('Raw profile'!H157>0,1,IF('Raw profile'!H260>0,2,0)) -> 2 | J39: =IF('Raw profile'!I157>0,1,IF('Raw profile'!I260>0,2,0)) -> 2 | K39: =IF('Raw profile'!J157>0,1,IF('Raw profile'!J260>0,2,0)) -> 2 | ... BK39: =IF('Raw profile'!BJ157>0,1,IF('Raw profile'!BJ260>0,2,0)) -> 0
B40: Growth | C40: ='Growth profile'!I49 -> 2031 | D40: =IF('Growth profile'!C157>0,1,IF('Growth profile'!C260>0,3,0)) -> 0 | E40: =IF('Growth profile'!D157>0,1,IF('Growth profile'!D260>0,3,0)) -> 0 | F40: =IF('Growth profile'!E157>0,1,IF('Growth profile'!E260>0,3,0)) -> 0 | G40: =IF('Growth profile'!F157>0,1,IF('Growth profile'!F260>0,3,0)) -> 0 | H40: =IF('Growth profile'!G157>0,1,IF('Growth profile'!G260>0,3,0)) -> 0 | I40: =IF('Growth profile'!H157>0,1,IF('Growth profile'!H260>0,3,0)) -> 1 | J40: =IF('Growth profile'!I157>0,1,IF('Growth profile'!I260>0,3,0)) -> 3 | K40: =IF('Growth profile'!J157>0,1,IF('Growth profile'!J260>0,3,0)) -> 3 | ... BK40: =IF('Growth profile'!BJ157>0,1,IF('Growth profile'!BJ260>0,3,0)) -> 0
B41: No penalty | C41: ='Growth (no penalty)'!I49 -> 2032 | D41: =IF('Growth (no penalty)'!C157>0,1,IF('Growth (no penalty)'!C260>0,4,0)) -> 0 | E41: =IF('Growth (no penalty)'!D157>0,1,IF('Growth (no penalty)'!D260>0,4,0)) -> 0 | F41: =IF('Growth (no penalty)'!E157>0,1,IF('Growth (no penalty)'!E260>0,4,0)) -> 0 | G41: =IF('Growth (no penalty)'!F157>0,1,IF('Growth (no penalty)'!F260>0,4,0)) -> 0 | H41: =IF('Growth (no penalty)'!G157>0,1,IF('Growth (no penalty)'!G260>0,4,0)) -> 0 | I41: =IF('Growth (no penalty)'!H157>0,1,IF('Growth (no penalty)'!H260>0,4,0)) -> 0 | J41: =IF('Growth (no penalty)'!I157>0,1,IF('Growth (no penalty)'!I260>0,4,0)) -> 1 | K41: =IF('Growth (no penalty)'!J157>0,1,IF('Growth (no penalty)'!J260>0,4,0)) -> 4 | ... BK41: =IF('Growth (no penalty)'!BJ157>0,1,IF('Growth (no penalty)'!BJ260>0,4,0)) -> 0
...

Sheet Comparison
A1: Project schedule comparison - raw vs growth (production objective), plus growth with no cash penalty
A2: Sorted by shift (largest deferral first). All values link to the profile sheets.
A4: Project | B4: Role | C4: Cost band | D4: Base BCR | E4: Cost ($M) | F4: Growth p.a. | G4: Start (raw) | H4: Start (growth) | I4: Shift (yrs) | J4: PV raw ($M) | K4: PV growth ($M) | L4: Benefits end (growth) | M4: Benefit yrs truncated (growth) | N4: Growth band | O4: Read-out | P4: Start (growth, no cash penalty) | Q4: Shift vs raw (no cash penalty)
A5: ='Growth profile'!A41 -> project 33 | B5: ='Growth profile'!B41 -> random growth | C5: ='Growth profile'!C41 -> 3 | D5: ='Growth profile'!D41 -> 3.38 | E5: ='Growth profile'!E41 -> 8.973675 | F5: ='Growth profile'!H41 -> 0.03 | G5: ='Raw profile'!I41 -> 2026 | H5: ='Growth profile'!I41 -> 2043 | I5: =H5-G5 -> 17 | J5: ='Raw profile'!O41 -> 30.236451 | K5: ='Growth profile'!O41 -> 69.481946 | L5: =MIN('Growth profile'!L41,2085) -> 2084 | M5: ='Growth profile'!N41 -> 0 | N5: =IF(F5<0,"shrinking",IF(F5<0.015,"under 1.5%",IF(F5<0.018,"1.5% to 1.8%","1.8% and over"))) -> 1.8% and over | O5: =IF(I5>0,IF(L5=2085,"Deferred - pinned to horizon end","Deferred"),IF(I5<0,"Accelerated","Unchanged")) -> Deferred | P5: ='Growth (no penalty)'!I41 -> 2044 | Q5: =P5-G5 -> 18
A6: ='Growth profile'!A51 -> project 48 | B6: ='Growth profile'!B51 -> random growth | C6: ='Growth profile'!C51 -> 1 | D6: ='Growth profile'!D51 -> 7 | E6: ='Growth profile'!E51 -> 1.006 | F6: ='Growth profile'!H51 -> 0.0299 | G6: ='Raw profile'!I51 -> 2026 | H6: ='Growth profile'!I51 -> 2043 | I6: =H6-G6 -> 17 | J6: ='Raw profile'!O51 -> 6.9459216 | K6: ='Growth profile'!O51 -> 15.899036 | L6: =MIN('Growth profile'!L51,2085) -> 2084 | M6: ='Growth profile'!N51 -> 0 | N6: =IF(F6<0,"shrinking",IF(F6<0.015,"under 1.5%",IF(F6<0.018,"1.5% to 1.8%","1.8% and over"))) -> 1.8% and over | O6: =IF(I6>0,IF(L6=2085,"Deferred - pinned to horizon end","Deferred"),IF(I6<0,"Accelerated","Unchanged")) -> Deferred | P6: ='Growth (no penalty)'!I51 -> 2044 | Q6: =P6-G6 -> 18
A7: ='Growth profile'!A83 -> project 125 | B7: ='Growth profile'!B83 -> random growth | C7: ='Growth profile'!C83 -> 5 | D7: ='Growth profile'!D83 -> 3.05 | E7: ='Growth profile'!E83 -> 94.762111 | F7: ='Growth profile'!H83 -> 0.0276 | G7: ='Raw profile'!I83 -> 2026 | H7: ='Growth profile'!I83 -> 2042 | I7: =H7-G7 -> 16 | J7: ='Raw profile'!O83 -> 284.79522 | K7: ='Growth profile'!O83 -> 589.3316 | L7: =MIN('Growth profile'!L83,2085) -> 2083 | M7: ='Growth profile'!N83 -> 0 | N7: =IF(F7<0,"shrinking",IF(F7<0.015,"under 1.5%",IF(F7<0.018,"1.5% to 1.8%","1.8% and over"))) -> 1.8% and over | O7: =IF(I7>0,IF(L7=2085,"Deferred - pinned to horizon end","Deferred"),IF(I7<0,"Accelerated","Unchanged")) -> Deferred | P7: ='Growth (no penalty)'!I83 -> 2044 | Q7: =P7-G7 -> 18
A8: ='Growth profile'!A56 -> project 56 | B8: ='Growth profile'!B56 -> random growth | C8: ='Growth profile'!C56 -> 1 | D8: ='Growth profile'!D56 -> 5.43 | E8: ='Growth profile'!E56 -> 0.05325 | F8: ='Growth profile'!H56 -> 0.0244 | G8: ='Raw profile'!I56 -> 2026 | H8: ='Growth profile'!I56 -> 2042 | I8: =H8-G8 -> 16 | J8: ='Raw profile'!O56 -> 0.2891475 | K8: ='Growth profile'!O56 -> 0.51625003 | L8: =MIN('Growth profile'!L56,2085) -> 2082 | M8: ='Growth profile'!N56 -> 0 | N8: =IF(F8<0,"shrinking",IF(F8<0.015,"under 1.5%",IF(F8<0.018,"1.5% to 1.8%","1.8% and over"))) -> 1.8% and over | O8: =IF(I8>0,IF(L8=2085,"Deferred - pinned to horizon end","Deferred"),IF(I8<0,"Accelerated","Unchanged")) -> Deferred | P8: ='Growth (no penalty)'!I56 -> 2045 | Q8: =P8-G8 -> 19
A9: ='Growth profile'!A64 -> project 84 | B9: ='Growth profile'!B64 -> random growth | C9: ='Growth profile'!C64 -> 1 | D9: ='Growth profile'!D64 -> 1.87 | E9: ='Growth profile'!E64 -> 1.1495637 | F9: ='Growth profile'!H64 -> 0.0291 | G9: ='Raw profile'!I64 -> 2026 | H9: ='Growth profile'!I64 -> 2042 | I9: =H9-G9 -> 16 | J9: ='Raw profile'!O64 -> 2.1496842 | K9: ='Growth profile'!O64 -> 4.5645555 | L9: =MIN('Growth profile'!L64,2085) -> 2082 | M9: ='Growth profile'!N64 -> 0 | N9: =IF(F9<0,"shrinking",IF(F9<0.015,"under 1.5%",IF(F9<0.018,"1.5% to 1.8%","1.8% and over"))) -> 1.8% and over | O9: =IF(I9>0,IF(L9=2085,"Deferred - pinned to horizon end","Deferred"),IF(I9<0,"Accelerated","Unchanged")) -> Deferred | P9: ='Growth (no penalty)'!I64 -> 2045 | Q9: =P9-G9 -> 19
A10: ='Growth profile'!A84 -> project 126 | B10: ='Growth profile'!B84 -> random growth | C10: ='Growth profile'!C84 -> 5 | D10: ='Growth profile'!D84 -> 2.92 | E10: ='Growth profile'!E84 -> 104.79906 | F10: ='Growth profile'!H84 -> 0.0266 | G10: ='Raw profile'!I84 -> 2026 | H10: ='Growth profile'!I84 -> 2041 | I10: =H10-G10 -> 15 | J10: ='Raw profile'!O84 -> 295.1268 | K10: ='Growth profile'!O84 -> 616.50866 | L10: =MIN('Growth profile'!L84,2085) -> 2084 | M10: ='Growth profile'!N84 -> 0 | N10: =IF(F10<0,"shrinking",IF(F10<0.015,"under 1.5%",IF(F10<0.018,"1.5% to 1.8%","1.8% and over"))) -> 1.8% and over | O10: =IF(I10>0,IF(L10=2085,"Deferred - pinned to horizon end","Deferred"),IF(I10<0,"Accelerated","Unchanged")) -> Deferred | P10: ='Growth (no penalty)'!I84 -> 2042 | Q10: =P10-G10 -> 16
A11: ='Growth profile'!A98 -> project 156 | B11: ='Growth profile'!B98 -> random growth | C11: ='Growth profile'!C98 -> 4 | D11: ='Growth profile'!D98 -> 3.2 | E11: ='Growth profile'!E98 -> 16.213995 | F11: ='Growth profile'!H98 -> 0.0274 | G11: ='Raw profile'!I98 -> 2026 | H11: ='Growth profile'!I98 -> 2040 | I11: =H11-G11 -> 14 | J11: ='Raw profile'!O98 -> 49.696442 | K11: ='Growth profile'!O98 -> 105.93552 | L11: =MIN('Growth profile'!L98,2085) -> 2083 | M11: ='Growth profile'!N98 -> 0 | N11: =IF(F11<0,"shrinking",IF(F11<0.015,"under 1.5%",IF(F11<0.018,"1.5% to 1.8%","1.8% and over"))) -> 1.8% and over | O11: =IF(I11>0,IF(L11=2085,"Deferred - pinned to horizon end","Deferred"),IF(I11<0,"Accelerated","Unchanged")) -> Deferred | P11: ='Growth (no penalty)'!I98 -> 2042 | Q11: =P11-G11 -> 16
A12: ='Growth profile'!A102 -> project 162 | B12: ='Growth profile'!B102 -> random growth | C12: ='Growth profile'!C102 -> 3 | D12: ='Growth profile'!D102 -> 2.94 | E12: ='Growth profile'!E102 -> 11.061426 | F12: ='Growth profile'!H102 -> 0.0246 | G12: ='Raw profile'!I102 -> 2027 | H12: ='Growth profile'!I102 -> 2041 | I12: =H12-G12 -> 14 | J12: ='Raw profile'!O102 -> 31.299626 | K12: ='Growth profile'!O102 -> 60.017609 | L12: =MIN('Growth profile'!L102,2085) -> 2083 | M12: ='Growth profile'!N102 -> 0 | N12: =IF(F12<0,"shrinking",IF(F12<0.015,"under 1.5%",IF(F12<0.018,"1.5% to 1.8%","1.8% and over"))) -> 1.8% and over | O12: =IF(I12>0,IF(L12=2085,"Deferred - pinned to horizon end","Deferred"),IF(I12<0,"Accelerated","Unchanged")) -> Deferred | P12: ='Growth (no penalty)'!I102 -> 2043 | Q12: =P12-G12 -> 16
A13: ='Growth profile'!A24 -> project 1 | B13: ='Growth profile'!B24 -> anchor: top BCR 7, +3% | C13: ='Growth profile'!C24 -> 4 | D13: ='Growth profile'!D24 -> 7 | E13: ='Growth profile'!E24 -> 36.329552 | F13: ='Growth profile'!H24 -> 0.03 | G13: ='Raw profile'!I24 -> 2026 | H13: ='Growth profile'!I24 -> 2039 | I13: =H13-G13 -> 13 | J13: ='Raw profile'!O24 -> 240.28604 | K13: ='Growth profile'!O24 -> 594.63487 | L13: =MIN('Growth profile'!L24,2085) -> 2084 | M13: ='Growth profile'!N24 -> 0 | N13: =IF(F13<0,"shrinking",IF(F13<0.015,"under 1.5%",IF(F13<0.018,"1.5% to 1.8%","1.8% and over"))) -> 1.8% and over | O13: =IF(I13>0,IF(L13=2085,"Deferred - pinned to horizon end","Deferred"),IF(I13<0,"Accelerated","Unchanged")) -> Deferred | P13: ='Growth (no penalty)'!I24 -> 2040 | Q13: =P13-G13 -> 14
A14: ='Growth profile'!A119 -> project 200 | B14: ='Growth profile'!B119 -> random growth | C14: ='Growth profile'!C119 -> 1 | D14: ='Growth profile'!D119 -> 1.97 | E14: ='Growth profile'!E119 -> 0.79345245 | F14: ='Growth profile'!H119 -> 0.0272 | G14: ='Raw profile'!I119 -> 2026 | H14: ='Growth profile'!I119 -> 2039 | I14: =H14-G14 -> 13 | J14: ='Raw profile'!O119 -> 1.5612809 | K14: ='Growth profile'!O119 -> 3.0838958 | L14: =MIN('Growth profile'!L119,2085) -> 2080 | M14: ='Growth profile'!N119 -> 0 | N14: =IF(F14<0,"shrinking",IF(F14<0.015,"under 1.5%",IF(F14<0.018,"1.5% to 1.8%","1.8% and over"))) -> 1.8% and over | O14: =IF(I14>0,IF(L14=2085,"Deferred - pinned to horizon end","Deferred"),IF(I14<0,"Accelerated","Unchanged")) -> Deferred | P14: ='Growth (no penalty)'!I119 -> 2044 | Q14: =P14-G14 -> 18
A15: ='Growth profile'!A70 -> project 100 | B15: ='Growth profile'!B70 -> random growth | C15: ='Growth profile'!C70 -> 4 | D15: ='Growth profile'!D70 -> 2.21 | E15: ='Growth profile'!E70 -> 17.984314 | F15: ='Growth profile'!H70 -> 0.0274 | G15: ='Raw profile'!I70 -> 2026 | H15: ='Growth profile'!I70 -> 2038 | I15: =H15-G15 -> 12 | J15: ='Raw profile'!O70 -> 39.386346 | K15: ='Growth profile'!O70 -> 77.531166 | L15: =MIN('Growth profile'!L70,2085) -> 2079 | M15: ='Growth profile'!N70 -> 0 | N15: =IF(F15<0,"shrinking",IF(F15<0.015,"under 1.5%",IF(F15<0.018,"1.5% to 1.8%","1.8% and over"))) -> 1.8% and over | O15: =IF(I15>0,IF(L15=2085,"Deferred - pinned to horizon end","Deferred"),IF(I15<0,"Accelerated","Unchanged")) -> Deferred | P15: ='Growth (no penalty)'!I70 -> 2044 | Q15: =P15-G15 -> 18
A16: ='Growth profile'!A29 -> project 12 | B16: ='Growth profile'!B29 -> random growth | C16: ='Growth profile'!C29 -> 2 | D16: ='Growth profile'!D29 -> 2.07 | E16: ='Growth profile'!E29 -> 2.9836078 | F16: ='Growth profile'!H29 -> 0.0231 | G16: ='Raw profile'!I29 -> 2026 | H16: ='Growth profile'!I29 -> 2037 | I16: =H16-G16 -> 11 | J16: ='Raw profile'!O29 -> 6.1478753 | K16: ='Growth profile'!O29 -> 10.404345 | L16: =MIN('Growth profile'!L29,2085) -> 2078 | M16: ='Growth profile'!N29 -> 0 | N16: =IF(F16<0,"shrinking",IF(F16<0.015,"under 1.5%",IF(F16<0.018,"1.5% to 1.8%","1.8% and over"))) -> 1.8% and over | O16: =IF(I16>0,IF(L16=2085,"Deferred - pinned to horizon end","Deferred"),IF(I16<0,"Accelerated","Unchanged")) -> Deferred | P16: ='Growth (no penalty)'!I29 -> 2044 | Q16: =P16-G16 -> 18
A17: ='Growth profile'!A112 -> project 184 | B17: ='Growth profile'!B112 -> random growth | C17: ='Growth profile'!C112 -> 2 | D17: ='Growth profile'!D112 -> 2.65 | E17: ='Growth profile'!E112 -> 2.823373 | F17: ='Growth profile'!H112 -> 0.0218 | G17: ='Raw profile'!I112 -> 2026 | H17: ='Growth profile'!I112 -> 2037 | I17: =H17-G17 -> 11 | J17: ='Raw profile'!O112 -> 7.4819384 | K17: ='Growth profile'!O112 -> 11.858082 | L17: =MIN('Growth profile'!L112,2085) -> 2077 | M17: ='Growth profile'!N112 -> 0 | N17: =IF(F17<0,"shrinking",IF(F17<0.015,"under 1.5%",IF(F17<0.018,"1.5% to 1.8%","1.8% and over"))) -> 1.8% and over | O17: =IF(I17>0,IF(L17=2085,"Deferred - pinned to horizon end","Deferred"),IF(I17<0,"Accelerated","Unchanged")) -> Deferred | P17: ='Growth (no penalty)'!I112 -> 2045 | Q17: =P17-G17 -> 19
A18: ='Growth profile'!A118 -> project 195 | B18: ='Growth profile'!B118 -> random growth | C18: ='Growth profile'!C118 -> 1 | D18: ='Growth profile'!D118 -> 1.96 | E18: ='Growth profile'!E118 -> 0.84528292 | F18: ='Growth profile'!H118 -> 0.0281 | G18: ='Raw profile'!I118 -> 2032 | H18: ='Growth profile'!I118 -> 2042 | I18: =H18-G18 -> 10 | J18: ='Raw profile'!O118 -> 1.4739021 | K18: ='Growth profile'!O118 -> 3.4715308 | L18: =MIN('Growth profile'!L118,2085) -> 2083 | M18: ='Growth profile'!N118 -> 0 | N18: =IF(F18<0,"shrinking",IF(F18<0.015,"under 1.5%",IF(F18<0.018,"1.5% to 1.8%","1.8% and over"))) -> 1.8% and over | O18: =IF(I18>0,IF(L18=2085,"Deferred - pinned to horizon end","Deferred"),IF(I18<0,"Accelerated","Unchanged")) -> Deferred | P18: ='Growth (no penalty)'!I118 -> 2044 | Q18: =P18-G18 -> 12
A19: ='Growth profile'!A32 -> project 20 | B19: ='Growth profile'!B32 -> random growth | C19: ='Growth profile'!C32 -> 2 | D19: ='Growth profile'!D32 -> 1.69 | E19: ='Growth profile'!E32 -> 1.8170941 | F19: ='Growth profile'!H32 -> 0.0192 | G19: ='Raw profile'!I32 -> 2026 | H19: ='Growth profile'!I32 -> 2035 | I19: =H19-G19 -> 9 | J19: ='Raw profile'!O32 -> 3.0655774 | K19: ='Growth profile'!O32 -> 4.5555424 | L19: =MIN('Growth profile'!L32,2085) -> 2076 | M19: ='Growth profile'!N32 -> 0 | N19: =IF(F19<0,"shrinking",IF(F19<0.015,"under 1.5%",IF(F19<0.018,"1.5% to 1.8%","1.8% and over"))) -> 1.8% and over | O19: =IF(I19>0,IF(L19=2085,"Deferred - pinned to horizon end","Deferred"),IF(I19<0,"Accelerated","Unchanged")) -> Deferred | P19: ='Growth (no penalty)'!I32 -> 2044 | Q19: =P19-G19 -> 18
A20: ='Growth profile'!A48 -> project 43 | B20: ='Growth profile'!B48 -> random growth | C20: ='Growth profile'!C48 -> 1 | D20: ='Growth profile'!D48 -> 1.52 | E20: ='Growth profile'!E48 -> 0.03815 | F20: ='Growth profile'!H48 -> 0.0184 | G20: ='Raw profile'!I48 -> 2026 | H20: ='Growth profile'!I48 -> 2035 | I20: =H20-G20 -> 9 | J20: ='Raw profile'!O48 -> 0.057988 | K20: ='Growth profile'!O48 -> 0.082479423 | L20: =MIN('Growth profile'!L48,2085) -> 2075 | M20: ='Growth profile'!N48 -> 0 | N20: =IF(F20<0,"shrinking",IF(F20<0.015,"under 1.5%",IF(F20<0.018,"1.5% to 1.8%","1.8% and over"))) -> 1.8% and over | O20: =IF(I20>0,IF(L20=2085,"Deferred - pinned to horizon end","Deferred"),IF(I20<0,"Accelerated","Unchanged")) -> Deferred | P20: ='Growth (no penalty)'!I48 -> 2045 | Q20: =P20-G20 -> 19
